Workbook

Sheet NCE_exp
A1: experiment | B1: exp_id | C1: round | D1: tank | E1: date | F1: light | G1: treatment | H1: location_T0 | I1: behaviour_T0 | J1: location_T5 | K1: behaviour_T5 | L1: location_T10 | M1: behaviour_T10 | N1: location_T20 | O1: behaviour_T20 | P1: location_T30 | Q1: behaviour_T30 | R1: location_T45 | S1: behaviour_T45 | T1: location_T60 | U1: behaviour_T60 | V1: location_T61 | W1: behaviour_T61 | X1: location_T65 | Y1: behaviour_T65 | Z1: location_T70 | AA1: behaviour_T70 | AB1: location_T80 | AC1: behaviour_T80 | AD1: location_T90 | AE1: behaviour_T90 | AF1: location_T120 | AG1: behaviour_T120 | AH1: location_T150 | AI1: behaviour_T150 | AJ1: location_T180 | AK1: behaviour_T180 | AL1: location_T210 | AM1: behaviour_T210 | AN1: location_T240 | AO1: behaviour_T240 | AP1: location_T245 | AQ1: behaviour_T245 | AR1: location_T260 | AS1: behaviour_T260 | AT1: location_T275 | AU1: behaviour_T275 | AV1: location_T290 | AW1: behaviour_T290 | AX1: location_T300 | AY1: behaviour_T300 | AZ1: notes_exp | BA1: koura_id | BB1: extra_koura_id | BC1: old_id | BD1: hold_tank | BE1: sex | BF1: size_class | BG1: size_mm1 | BH1: weight_g1 | BI1: legs1 | BJ1: claws1 | BK1: antenna1 | BL1: note | BM1: size_mm2 | BN1: weight_g2 | BO1: legs2 | BP1: claws2 | BQ1: antenna2 | BR1: moult_date | BS1: notes_koura
A2: NCE1 | B2: 1 | C2: 1 | D2: 1 | E2: 45931 | F2: light | G2: catfish | H2: floor | I2: static | J2: ref_back | K2: static | L2: ref_back | M2: static | N2: ref_back | O2: static | P2: ref_back | Q2: static | R2: ref_back | S2: static | T2: ref_back | U2: static | V2: ref_back | W2: static | X2: ref_back | Y2: static | Z2: ref_back | AA2: static | AB2: ref_back | AC2: static | AD2: ref_back | AE2: static | AF2: ref_back | AG2: static | AH2: ref_back | AI2: static | AJ2: ref_back | AK2: static | AL2: ref_back | AM2: static | AN2: ref_back | AO2: static | AP2: ref_back | AQ2: static | AR2: ref_back | AS2: static | AT2: ref_back | AU2: static | AV2: ref_back | AW2: static | AX2: ref_back | AY2: static | BA2: 41 | BB2: 41 | BC2: 2 | BD2: 1 | BE2: M | BF2: M | BG2: 27.25 | BH2: 14 | BI2: 8 | BJ2: 2
A3: NCE1 | B3: 2 | C3: 1 | D3: 2 | E3: 45931 | F3: light | G3: eel | H3: floor | I3: static | J3: wall | K3: static | L3: wall | M3: static | N3: wall | O3: static | P3: barrier | Q3: static | R3: barrier | S3: static | T3: ref_back | U3: static | V3: ref_back | W3: static | X3: ref_back | Y3: static | Z3: ref_back | AA3: static | AB3: ref_back | AC3: static | AD3: ref_back | AE3: static | AF3: ref_back | AG3: static | AH3: ref_back | AI3: static | AJ3: ref_back | AK3: static | AL3: ref_back | AM3: static | AN3: ref_back | AO3: static | AP3: ref_back | AQ3: static | AR3: ref_back | AS3: static | AT3: ref_back | AU3: static | AV3: ref_back | AW3: static | AX3: ref_back | AY3: static | BA3: 42 | BB3: 42 | BC3: 3 | BD3: 2 | BE3: M | BF3: M | BG3: 25.97 | BH3: 11 | BI3: 8 | BJ3: 2
A4: NCE1 | B4: 3 | C4: 1 | D4: 3 | E4: 45931 | F4: light | G4: control | H4: barrier | I4: walk | J4: wall | K4: static | L4: wall | M4: static | N4: barrier | O4: static | P4: barrier | Q4: walk | R4: wall | S4: walk | T4: barrier | U4: static | V4: barrier | W4: static | X4: barrier | Y4: static | Z4: barrier | AA4: static | AB4: barrier | AC4: climb | AD4: wall | AE4: static | AF4: ref_next | AG4: static | AH4: ref_back | AI4: static | AJ4: ref_back | AK4: static | AL4: ref_back | AM4: static | AN4: ref_back | AO4: static | AP4: ref_back | AQ4: static | AR4: ref_back | AS4: static | AT4: ref_back | AU4: static | AV4: ref_back | AW4: static | AX4: ref_back | AY4: static | BA4: 43 | BB4: 43 | BC4: 5 | BD4: 3 | BE4: M | BF4: M | BG4: 23.71 | BH4: 9 | BI4: 8 | BJ4: 2
A5: NCE1 | B5: 4 | C5: 1 | D5: 4 | E5: 45931 | F5: light | G5: catfish | H5: ref_open | I5: static | J5: ref_back | K5: static | L5: ref_back | M5: static | N5: ref_back | O5: static | P5: ref_back | Q5: static | R5: ref_back | S5: static | T5: ref_back | U5: static | V5: ref_back | W5: static | X5: ref_back | Y5: static | Z5: ref_back | AA5: static | AB5: ref_back | AC5: static | AD5: ref_back | AE5: static | AF5: ref_next | AG5: static | AH5: ref_back | AI5: static | AJ5: ref_back | AK5: static | AL5: ref_back | AM5: static | AN5: ref_back | AO5: static | AP5: ref_back | AQ5: static | AR5: ref_back | AS5: static | AT5: ref_back | AU5: static | AV5: ref_back | AW5: static | AX5: ref_back | AY5: static | BA5: 44 | BB5: 44 | BC5: 9 | BD5: 4 | BE5: M | BF5: M | BG5: 24.7 | BH5: 10 | BI5: 7 | BJ5: 2
A6: NCE1 | B6: 5 | C6: 1 | D6: 5 | E6: 45931 | F6: light | G6: eel | H6: barrier | I6: static | J6: wall | K6: walk | L6: wall | M6: walk | N6: wall | O6: walk | P6: barrier | Q6: climb | R6: wall | S6: walk | T6: wall | U6: static | V6: floor | W6: walk | X6: wall | Y6: static | Z6: ref_next | AA6: static | AB6: barrier | AC6: static | AD6: barrier | AE6: climb | AF6: barrier | AG6: climb | AH6: barrier | AI6: climb | AJ6: barrier | AK6: climb | AL6: barrier | AM6: climb | AN6: barrier | AO6: climb | AP6: barrier | AQ6: walk | AR6: barrier | AS6: climb | AT6: barrier | AU6: climb | AV6: barrier | AW6: climb | AX6: barrier | AY6: climb | BA6: 45 | BB6: 45 | BC6: 11 | BD6: 5 | BE6: M | BF6: M | BG6: 29.49 | BH6: 17 | BI6: 8 | BJ6: 2
A7: NCE1 | B7: 6 | C7: 1 | D7: 6 | E7: 45931 | F7: light | G7: control | H7: ref_back | I7: static | J7: wall | K7: static | L7: wall | M7: walk | N7: barrier | O7: static | P7: wall | Q7: static | R7: barrier | S7: climb | T7: barrier | U7: climb | V7: barrier | W7: climb | X7: barrier | Y7: climb | Z7: barrier | AA7: climb | AB7: barrier | AC7: climb | AD7: barrier | AE7: climb | AF7: ref_next | AG7: static | AH7: barrier | AI7: climb | AJ7: barrier | AK7: climb | AL7: wall | AM7: walk | AN7: ref_next | AO7: static | AP7: ref_open | AQ7: static | AR7: ref_open | AS7: static | AT7: ref_open | AU7: static | AV7: ref_open | AW7: static | AX7: ref_open | AY7: static | BA7: 46 | BB7: 46 | BC7: 12 | BD7: 6 | BE7: M | BF7: M | BG7: 24.57 | BH7: 10 | BI7: 8 | BJ7: 2
A8: NCE1 | B8: 7 | C8: 1 | D8: 7 | E8: 45931 | F8: light | G8: catfish | H8: floor | I8: static | J8: ref_back | K8: static | L8: ref_back | M8: static | N8: ref_back | O8: static | P8: ref_back | Q8: static | R8: ref_back | S8: static | T8: ref_back | U8: static | V8: ref_back | W8: static | X8: ref_back | Y8: static | Z8: ref_back | AA8: static | AB8: ref_back | AC8: static | AD8: ref_back | AE8: static | AF8: ref_back | AG8: static | AH8: ref_back | AI8: static | AJ8: ref_back | AK8: static | AL8: ref_back | AM8: static | AN8: ref_back | AO8: static | AP8: ref_back | AQ8: static | AR8: ref_back | AS8: static | AT8: ref_back | AU8: static | AV8: ref_back | AW8: static | AX8: ref_back | AY8: static | BA8: 47 | BB8: 47 | BC8: 13 | BD8: 7 | BE8: M | BF8: M | BG8: 23.84 | BH8: 8 | BI8: 8 | BJ8: 2
A9: NCE1 | B9: 8 | C9: 1 | D9: 8 | E9: 45931 | F9: light | G9: eel | H9: ref_next | I9: static | J9: ref_next | K9: static | L9: ref_next | M9: static | N9: ref_back | O9: static | P9: ref_back | Q9: static | R9: ref_back | S9: static | T9: ref_back | U9: static | V9: ref_back | W9: static | X9: ref_back | Y9: static | Z9: ref_back | AA9: static | AB9: ref_back | AC9: static | AD9: ref_back | AE9: static | AF9: ref_back | AG9: static | AH9: ref_back | AI9: static | AJ9: ref_back | AK9: static | AL9: ref_back | AM9: static | AN9: ref_back | AO9: static | AP9: ref_back | AQ9: static | AR9: ref_back | AS9: static | AT9: ref_back | AU9: static | AV9: ref_back | AW9: static | AX9: ref_back | AY9: static | BA9: 48 | BB9: 48 | BC9: 15 | BD9: 8 | BE9: M | BF9: M | BG9: 24.17 | BH9: 8 | BI9: 7 | BJ9: 1 | BK9: 2 | BR9: 45924
A10: NCE1 | B10: 9 | C10: 2 | D10: 1 | E10: 45932 | F10: light | G10: control | H10: floor | I10: static | J10: floor | K10: static | L10: barrier | M10: climb | N10: barrier | O10: climb | P10: barrier | Q10: climb | R10: barrier | S10: climb | T10: barrier | U10: climb | V10: barrier | W10: climb | X10: barrier | Y10: climb | Z10: barrier | AA10: climb | AB10: barrier | AC10: climb | AD10: barrier | AE10: static | AF10: ref_back | AG10: static | AH10: ref_back | AI10: static | AL10: ref_back | AM10: static | AN10: ref_back | AO10: static | AP10: ref_back | AQ10: static | AR10: ref_back | AS10: static | AT10: ref_back | AU10: static | AV10: ref_back | AW10: static | AX10: ref_back | AY10: static | BA10: 49 | BB10: 49 | BC10: 16 | BD10: 9 | BE10: M | BF10: M | BG10: 25.8 | BH10: 11 | BI10: 7 | BJ10: 1
A11: NCE1 | B11: 10 | C11: 2 | D11: 2 | E11: 45932 | F11: light | G11: catfish | H11: barrier | I11: static | J11: barrier | K11: static | L11: barrier | M11: static | N11: barrier | O11: static | P11: barrier | Q11: static | R11: barrier | S11: climb | T11: barrier | U11: static | V11: ref_back | W11: static | X11: ref_back | Y11: static | Z11: ref_back | AA11: static | AB11: ref_back | AC11: static | AD11: ref_back | AE11: static | AF11: ref_back | AG11: static | AH11: ref_back | AI11: static | AL11: ref_back | AM11: static | AN11: ref_back | AO11: static | AP11: ref_back | AQ11: static | AR11: ref_back | AS11: static | AT11: ref_open | AU11: static | AV11: ref_back | AW11: static | AX11: ref_back | AY11: static | BA11: 50 | BB11: 50 | BC11: 22 | BD11: 10 | BE11: M | BF11: M | BG11: 28.47 | BH11: 14 | BI11: 8 | BJ11: 1 | BK11: 2 | BR11: 45901
A12: NCE1 | B12: 11 | C12: 2 | D12: 3 | E12: 45932 | F12: light | G12: eel | H12: floor | I12: static | J12: wall | K12: static | L12: barrier | M12: static | N12: barrier | O12: static | P12: barrier | Q12: static | R12: barrier | S12: static | T12: barrier | U12: static | V12: floor | W12: static | X12: barrier | Y12: static | Z12: barrier | AA12: static | AB12: barrier | AC12: static | AD12: barrier | AE12: static | AF12: barrier | AG12: static | AH12: barrier | AI12: climb | AL12: wall | AM12: static | AN12: barrier | AO12: static | AP12: barrier | AQ12: static | AR12: barrier | AS12: static | AT12: barrier | AU12: static | AV12: barrier | AW12: static | AX12: barrier | AY12: static | BA12: 51 | BB12: 51 | BC12: 23 | BD12: 11 | BE12: M | BF12: M | BG12: 23.85 | BH12: 8 | BI12: 8 | BJ12: 2
A13: NCE1 | B13: 12 | C13: 2 | D13: 4 | E13: 45932 | F13: light | G13: control | H13: floor | I13: static | J13: barrier | K13: static | L13: ref_back | M13: static | N13: ref_back | O13: static | P13: ref_back | Q13: static | R13: ref_back | S13: static | T13: ref_back | U13: static | V13: ref_back | W13: static | X13: ref_back | Y13: static | Z13: ref_back | AA13: static | AB13: ref_back | AC13: static | AD13: ref_back | AE13: static | AF13: ref_back | AG13: static | AH13: ref_back | AI13: static | AL13: ref_back | AM13: static | AN13: ref_back | AO13: static | AP13: ref_back | AQ13: static | AR13: ref_back | AS13: static | AT13: ref_back | AU13: static | AV13: ref_back | AW13: static | AX13: ref_back | AY13: static | BA13: 52 | BB13: 52 | BC13: 24 | BD13: 12 | BE13: M | BF13: M | BG13: 28.17 | BH13: 15 | BI13: 8 | BJ13: 2
A14: NCE1 | B14: 13 | C14: 2 | D14: 5 | E14: 45932 | F14: light | G14: catfish | H14: ref_next | I14: static | J14: barrier | K14: climb | L14: floor | M14: walk | N14: barrier | O14: climb | P14: barrier | Q14: climb | R14: barrier | S14: climb | T14: barrier | U14: climb | V14: barrier | W14: climb | X14: barrier | Y14: climb | Z14: barrier | AA14: climb | AB14: barrier | AC14: climb | AD14: barrier | AE14: climb | AF14: barrier | AG14: climb | AH14: barrier | AI14: climb | AL14: barrier | AM14: climb | AN14: barrier | AO14: climb | AP14: barrier | AQ14: climb | AR14: barrier | AS14: climb | AT14: barrier | AU14: climb | AV14: barrier | AW14: climb | AX14: barrier | AY14: climb | BA14: 53 | BB14: 53 | BC14: 26 | BD14: 13 | BE14: M | BF14: M | BG14: 28.33 | BH14: 17 | BI14: 8 | BJ14: 2 | BK14: 2 | BR14: 45929
A15: NCE1 | B15: 14 | C15: 2 | D15: 6 | E15: 45932 | F15: light | G15: eel | H15: ref_back | I15: static | J15: ref_next | K15: static | L15: barrier | M15: static | N15: barrier | O15: static | P15: barrier | Q15: climb | R15: barrier | S15: climb | T15: ref_next | U15: static | V15: ref_next | W15: static | X15: ref_next | Y15: static | Z15: ref_next | AA15: static | AB15: barrier | AC15: static | AD15: barrier | AE15: static | AF15: wall | AG15: static | AH15: barrier | AI15: climb | AL15: barrier | AM15: climb | AN15: barrier | AO15: climb | AP15: barrier | AQ15: climb | AR15: barrier | AS15: climb | AT15: barrier | AU15: climb | AV15: barrier | AW15: climb | AX15: barrier | AY15: climb | BA15: 54 | BB15: 54 | BC15: 28 | BD15: 14 | BE15: M | BF15: M | BG15: 26.42 | BH15: 13 | BI15: 8 | BJ15: 2 | BK15: 2 | BR15: 45904
A16: NCE1 | B16: 15 | C16: 2 | D16: 7 | E16: 45932 | F16: light | G16: control | H16: floor | I16: static | J16: wall | K16: static | L16: barrier | M16: static | N16: ref_back | O16: static | P16: barrier | Q16: static | R16: barrier | S16: static | T16: barrier | U16: static | V16: barrier | W16: static | X16: barrier | Y16: static | Z16: barrier | AA16: static | AB16: barrier | AC16: static | AD16: barrier | AE16: static | AF16: barrier | AG16: static | AH16: barrier | AI16: static | AL16: barrier | AM16: static | AN16: barrier | AO16: static | AP16: barrier | AQ16: static | AR16: barrier | AS16: static | AT16: barrier | AU16: static | AV16: barrier | AW16: static | AX16: barrier | AY16: static | BA16: 55 | BB16: 55 | BC16: 29 | BD16: 15 | BE16: M | BF16: M | BG16: 29.97 | BH16: 17 | BI16: 8 | BJ16: 2 | BK16: 2 | BR16: 45902
A17: NCE1 | B17: 16 | C17: 2 | D17: 8 | E17: 45932 | F17: light | G17: catfish | H17: floor | I17: static | J17: wall | K17: static | L17: ref_back | M17: static | N17: ref_open | O17: static | P17: ref_back | Q17: static | R17: ref_open | S17: static | T17: ref_open | U17: static | V17: ref_back | W17: static | X17: ref_back | Y17: static | Z17: ref_back | AA17: static | AB17: ref_back | AC17: static | AD17: ref_back | AE17: static | AF17: ref_back | AG17: static | AH17: ref_open | AI17: static | AL17: ref_open | AM17: static | AN17: ref_back | AO17: static | AP17: ref_back | AQ17: static | AR17: ref_open | AS17: static | AT17: ref_open | AU17: static | AV17: ref_back | AW17: static | AX17: ref_back | AY17: static | BA17: 56 | BB17: 56 | BC17: 30 | BD17: 16 | BE17: M | BF17: M | BG17: 27.18 | BH17: 14 | BI17: 7 | BJ17: 2 | BK17: 2
A18: NCE1 | B18: 17 | C18: 3 | D18: 1 | E18: 45933 | F18: light | G18: eel | H18: ref_back | I18: static | J18: ref_back | K18: static | L18: ref_back | M18: static | N18: ref_back | O18: static | P18: ref_back | Q18: static | R18: ref_back | S18: static | T18: ref_back | U18: static | V18: ref_back | W18: static | X18: ref_back | Y18: static | Z18: ref_back | AA18: static | AB18: ref_back | AC18: static | AD18: ref_back | AE18: static | AF18: ref_back | AG18: static | AH18: ref_back | AI18: static | AL18: ref_back | AM18: static | AN18: ref_back | AO18: static | AP18: ref_back | AQ18: static | AR18: ref_back | AS18: static | AT18: ref_back | AU18: static | AV18: ref_back | AW18: static | AX18: ref_back | AY18: static | BA18: 57 | BB18: 57 | BD18: 1 | BE18: M | BF18: M | BG18: 27.03 | BH18: 13 | BI18: 8 | BJ18: 2 | BK18: 2
A19: NCE1 | B19: 18 | C19: 3 | D19: 2 | E19: 45933 | F19: light | G19: control | H19: ref_back | I19: static | J19: ref_back | K19: static | L19: ref_back | M19: static | N19: barrier | O19: static | P19: barrier | Q19: climb | R19: ref_back | S19: static | T19: ref_back | U19: static | V19: ref_back | W19: static | X19: ref_back | Y19: static | Z19: ref_back | AA19: static | AB19: ref_back | AC19: static | AD19: ref_back | AE19: static | AF19: ref_back | AG19: static | AH19: ref_back | AI19: static | AL19: ref_back | AM19: static | AN19: ref_back | AO19: static | AP19: ref_back | AQ19: static | AR19: ref_back | AS19: static | AT19: ref_back | AU19: static | AV19: ref_back | AW19: static | AX19: ref_back | AY19: static | BA19: 58 | BB19: 58 | BD19: 2 | BE19: M | BF19: M | BG19: 26.88 | BH19: 13 | BI19: 8 | BJ19: 0 | BK19: 2
A20: NCE1 | B20: 19 | C20: 3 | D20: 3 | E20: 45933 | F20: light | G20: catfish | H20: ref_next | I20: static | J20: wall | K20: static | L20: ref_back | M20: static | N20: ref_back | O20: static | P20: ref_back | Q20: static | R20: barrier | S20: climb | T20: ref_back | U20: static | V20: ref_back | W20: static | X20: ref_back | Y20: static | Z20: ref_back | AA20: static | AB20: ref_back | AC20: static | AD20: ref_back | AE20: static | AF20: ref_back | AG20: static | AH20: ref_back | AI20: static | AL20: ref_back | AM20: static | AN20: ref_back | AO20: static | AP20: ref_back | AQ20: static | AR20: ref_back | AS20: static | AT20: ref_back | AU20: static | AV20: ref_back | AW20: static | AX20: ref_back | AY20: static | BA20: 59 | BB20: 59 | BD20: 3 | BE20: M | BF20: M | BG20: 27.34 | BH20: 8 | BI20: 8 | BJ20: 1 | BK20: 2
A21: NCE1 | B21: 20 | C21: 3 | D21: 4 | E21: 45933 | F21: light | G21: eel | H21: ref_next | I21: static | J21: ref_next | K21: static | L21: ref_back | M21: static | N21: ref_back | O21: static | P21: ref_back | Q21: static | R21: ref_back | S21: static | T21: ref_back | U21: static | V21: ref_back | W21: static | X21: ref_back | Y21: static | Z21: ref_back | AA21: static | AB21: ref_back | AC21: static | AD21: ref_back | AE21: static | AF21: ref_back | AG21: static | AH21: ref_back | AI21: static | AL21: ref_back | AM21: static | AN21: ref_back | AO21: static | AP21: ref_back | AQ21: static | AR21: ref_back | AS21: static | AT21: ref_back | AU21: static | AV21: ref_back | AW21: static | AX21: ref_back | AY21: static | BA21: 60 | BB21: 60 | BD21: 4 | BE21: M | BF21: M | BG21: 29.45 | BH21: 16 | BI21: 8 | BJ21: 2 | BK21: 2
A22: NCE1 | B22: 21 | C22: 3 | D22: 5 | E22: 45933 | F22: light | G22: control | H22: ref_back | I22: static | J22: barrier | K22: climb | L22: ref_back | M22: static | N22: barrier | O22: climb | P22: barrier | Q22: climb | R22: barrier | S22: climb | T22: barrier | U22: climb | V22: barrier | W22: climb | X22: barrier | Y22: climb | Z22: barrier | AA22: climb | AB22: barrier | AC22: climb | AD22: barrier | AE22: climb | AF22: barrier | AG22: climb | AH22: barrier | AI22: climb | AL22: barrier | AM22: climb | AN22: barrier | AO22: climb | AP22: barrier | AQ22: climb | AR22: barrier | AS22: climb | AT22: ref_open | AU22: static | AV22: barrier | AW22: climb | AX22: ref_open | AY22: static | BA22: 61 | BB22: 61 | BD22: 5 | BE22: M | BF22: M | BG22: 26.72 | BH22: 9 | BI22: 8 | BJ22: 2 | BK22: 2
A23: NCE1 | B23: 22 | C23: 3 | D23: 6 | E23: 45933 | F23: light | G23: catfish | H23: barrier | I23: static | J23: barrier | K23: climb | L23: barrier | M23: climb | N23: barrier | O23: climb | P23: barrier | Q23: climb | R23: barrier | S23: climb | T23: barrier | U23: climb | V23: barrier | W23: climb | X23: barrier | Y23: climb | Z23: barrier | AA23: climb | AB23: barrier | AC23: climb | AD23: barrier | AE23: climb | AF23: barrier | AG23: climb | AH23: barrier | AI23: climb | AL23: barrier | AM23: climb | AN23: barrier | AO23: static | AP23: barrier | AQ23: static | AR23: wall | AS23: walk | AT23: barrier | AU23: climb | AV23: barrier | AW23: climb | AX23: barrier | AY23: climb | BA23: 46 | BB23: 62 | BC23: 12 | BD23: 6 | BE23: M | BF23: M | BG23: 25.61 | BH23: 11 | BI23: 8 | BJ23: 2 | BK23: 2
A24: NCE1 | B24: 23 | C24: 3 | D24: 7 | E24: 45933 | F24: light | G24: eel | H24: ref_back | I24: static | J24: barrier | K24: static | L24: barrier | M24: climb | N24: wall | O24: static | P24: wall | Q24: static | R24: barrier | S24: static | T24: floor | U24: static | V24: floor | W24: walk | X24: wall | Y24: static | Z24: wall | AA24: static | AB24: ref_next | AC24: static | AD24: wall | AE24: static | AF24: barrier | AG24: static | AH24: barrier | AI24: climb | AL24: barrier | AM24: climb | AN24: barrier | AO24: climb | AP24: barrier | AQ24: climb | AR24: barrier | AS24: climb | AT24: barrier | AU24: climb | AV24: ref_next | AW24: static | AX24: barrier | AY24: climb | AZ24: felt out at 58:00 put back in | BA24: 63 | BB24: 63 | BD24: 7 | BE24: M | BF24: M | BG24: 23.58 | BH24: 10 | BI24: 8 | BJ24: 1 | BK24: 2
A25: NCE1 | B25: 24 | C25: 3 | D25: 8 | E25: 45933 | F25: light | G25: control | H25: ref_next | I25: static | J25: floor | K25: static | L25: floor | M25: static | N25: ref_open | O25: static | P25: barrier | Q25: climb | R25: wall | S25: static | T25: wall | U25: static | V25: wall | W25: static | X25: wall | Y25: static | Z25: floor | AA25: walk | AB25: ref_next | AC25: static | AD25: ref_back | AE25: static | AF25: ref_back | AG25: static | AH25: ref_back | AI25: static | AL25: ref_back | AM25: static | AN25: barrier | AO25: climb | AP25: ref_next | AQ25: static | AR25: ref_back | AS25: static | AT25: ref_open | AU25: static | AV25: ref_open | AW25: static | AX25: ref_open | AY25: static | BA25: 43 | BB25: 64 | BC25: 5 | BD25: 8 | BE25: M | BF25: M | BG25: 24.67 | BH25: 9 | BI25: 8 | BJ25: 1 | BK25: 2
A26: NCE1 | B26: 25 | C26: 4 | D26: 1 | E26: 45936 | F26: light | G26: catfish | H26: ref_next | I26: static | J26: ref_back | K26: static | L26: ref_back | M26: static | N26: ref_back | O26: static | P26: ref_back | Q26: static | R26: ref_back | S26: static | T26: ref_back | U26: static | V26: ref_back | W26: static | X26: ref_back | Y26: static | Z26: ref_back | AA26: static | AB26: ref_back | AC26: static | AD26: ref_back | AE26: static | AF26: ref_back | AG26: static | AH26: ref_back | AI26: static | AL26: ref_back | AM26: static | AN26: ref_back | AO26: static | AP26: ref_back | AQ26: static | AR26: ref_back | AS26: static | AT26: ref_back | AU26: static | AV26: ref_back | AW26: static | AX26: ref_back | AY26: static | BA26: 65 | BB26: 65 | BD26: 9 | BE26: M | BF26: M | BG26: 26.79 | BH26: 11 | BI26: 6 | BJ26: 0 | BK26: 2
A27: NCE1 | B27: 26 | C27: 4 | D27: 2 | E27: 45936 | F27: light | G27: eel | H27: wall | I27: static | J27: barrier | K27: climb | L27: barrier | M27: climb | N27: barrier | O27: climb | P27: barrier | Q27: climb | R27: barrier | S27: climb | T27: wall | U27: static | V27: wall | W27: static | X27: wall | Y27: static | Z27: wall | AA27: static | AB27: wall | AC27: static | AD27: barrier | AE27: climb | AF27: ref_open | AG27: static | AH27: barrier | AI27: static | AL27: barrier | AM27: climb | AN27: barrier | AO27: climb | AP27: barrier | AQ27: climb | AR27: barrier | AS27: climb | AT27: barrier | AU27: climb | AV27: barrier | AW27: climb | AX27: barrier | AY27: climb | BA27: 66 | BB27: 66 | BD27: 10 | BE27: M | BF27: M | BG27: 26.79 | BH27: 12 | BI27: 8 | BJ27: 2 | BK27: 2
A28: NCE1 | B28: 27 | C28: 4 | D28: 3 | E28: 45936 | F28: light | G28: control | H28: ref_back | I28: static | J28: ref_back | K28: static | L28: ref_back | M28: static | N28: ref_back | O28: static | P28: ref_back | Q28: static | R28: ref_back | S28: static | T28: ref_back | U28: static | V28: ref_back | W28: static | X28: ref_back | Y28: static | Z28: ref_back | AA28: static | AB28: ref_back | AC28: static | AD28: ref_back | AE28: static | AF28: ref_back | AG28: static | AH28: ref_back | AI28: static | AL28: ref_back | AM28: static | AN28: ref_open | AO28: static | AP28: ref_back | AQ28: static | AR28: ref_back | AS28: static | AT28: ref_back | AU28: static | AV28: ref_back | AW28: static | AX28: ref_back | AY28: static | BA28: 67 | BB28: 67 | BD28: 11 | BE28: M | BF28: M | BG28: 25.21 | BH28: 9 | BI28: 6 | BJ28: 2 | BK28: 2
A29: NCE1 | B29: 28 | C29: 4 | D29: 4 | E29: 45936 | F29: light | G29: catfish | H29: ref_next | I29: static | J29: barrier | K29: static | L29: barrier | M29: static | N29: wall | O29: static | P29: barrier | Q29: climb | R29: barrier | S29: static | T29: barrier | U29: climb | V29: barrier | W29: climb | X29: barrier | Y29: climb | Z29: barrier | AA29: climb | AB29: wall | AC29: static | AD29: ref_next | AE29: static | AF29: barrier | AG29: climb | AH29: barrier | AI29: climb | AL29: barrier | AM29: static | AN29: barrier | AO29: climb | AP29: barrier | AQ29: climb | AR29: barrier | AS29: climb | AT29: barrier | AU29: climb | AV29: barrier | AW29: static | AX29: barrier | AY29: static | BA29: 68 | BB29: 68 | BD29: 12 | BE29: M | BF29: M | BG29: 24.69 | BH29: 9 | BI29: 8 | BJ29: 2 | BK29: 2
A30: NCE1 | B30: 29 | C30: 4 | D30: 5 | E30: 45936 | F30: light | G30: eel | H30: floor | I30: walk | J30: ref_next | K30: static | L30: floor | M30: static | N30: barrier | O30: climb | P30: barrier | Q30: climb | R30: barrier | S30: climb | T30: barrier | U30: static | V30: barrier | W30: static | X30: barrier | Y30: static | Z30: barrier | AA30: static | AB30: ref_next | AC30: static | AD30: floor | AE30: static | AF30: barrier | AG30: static | AH30: barrier | AI30: static | AL30: ref_back | AM30: static | AN30: ref_back | AO30: static | AP30: ref_back | AQ30: static | AR30: ref_back | AS30: static | AT30: ref_back | AU30: static | AV30: ref_back | AW30: static | AX30: ref_back | AY30: static | BA30: 69 | BB30: 69 | BC30: 33 | BD30: 13 | BE30: M | BF30: M | BG30: 28.29 | BH30: 13 | BI30: 8 | BJ30: 2 | BK30: 2
A31: NCE1 | B31: 30 | C31: 4 | D31: 6 | E31: 45936 | F31: light | G31: control | H31: wall | I31: static | J31: ref_next | K31: static | L31: ref_back | M31: static | N31: ref_next | O31: static | P31: barrier | Q31: walk | R31: ref_back | S31: static | T31: ref_back | U31: static | V31: ref_back | W31: static | X31: ref_back | Y31: static | Z31: ref_back | AA31: static | AB31: ref_back | AC31: static | AD31: ref_back | AE31: static | AF31: ref_back | AG31: static | AH31: ref_back | AI31: static | AL31: ref_back | AM31: static | AN31: ref_back | AO31: static | AP31: ref_back | AQ31: static | AR31: ref_back | AS31: static | AT31: ref_back | AU31: static | AV31: ref_back | AW31: static | AX31: ref_back | AY31: static | BA31: 70 | BB31: 70 | BC31: 70 | BD31: 14 | BE31: M | BF31: M | BG31: 25.98 | BH31: 13 | BI31: 8 | BJ31: 2 | BK31: 2
A32: NCE1 | B32: 31 | C32: 4 | D32: 7 | E32: 45936 | F32: light | G32: catfish | H32: wall | I32: static | J32: wall | K32: static | L32: barrier | M32: static | N32: ref_open | O32: static | P32: barrier | Q32: walk | R32: ref_back | S32: static | T32: ref_back | U32: static | V32: ref_back | W32: static | X32: ref_back | Y32: static | Z32: ref_back | AA32: static | AB32: ref_open | AC32: static | AD32: ref_open | AE32: static | AF32: floor | AG32: static | AH32: ref_next | AI32: static | AL32: ref_back | AM32: static | AN32: ref_back | AO32: static | AP32: ref_back | AQ32: static | AR32: ref_back | AS32: static | AT32: ref_back | AU32: static | AV32: ref_back | AW32: static | AX32: ref_back | AY32: static | BA32: 71 | BB32: 71 | BC32: 51 | BD32: 15 | BE32: M | BF32: M | BG32: 26.79 | BH32: 10 | BI32: 7 | BJ32: 0 | BK32: 2
A33: NCE1 | B33: 32 | C33: 4 | D33: 8 | E33: 45936 | F33: light | G33: eel | H33: floor | I33: static | J33: ref_next | K33: static | L33: wall | M33: static | N33: wall | O33: static | P33: barrier | Q33: walk | R33: floor | S33: static | T33: barrier | U33: climb | V33: barrier | W33: climb | X33: barrier | Y33: climb | Z33: barrier | AA33: climb | AB33: wall | AC33: static | AD33: ref_next | AE33: static | AF33: ref_next | AG33: static | AH33: ref_next | AI33: static | AL33: ref_next | AM33: static | AN33: ref_next | AO33: static | AP33: wall | AQ33: static | AR33: ref_next | AS33: static | AT33: ref_next | AU33: static | AV33: ref_next | AW33: static | AX33: wall | AY33: static | BA33: 72 | BB33: 72 | BD33: 16 | BE33: M | BF33: M | BG33: 28.22 | BH33: 11 | BI33: 8 | BJ33: 2 | BK33: 2
A34: NCE2 | B34: 33 | C34: 5 | D34: 1 | E34: 45943 | F34: dark | G34: catfish | H34: floor | I34: walk | J34: ref_next | K34: static | L34: ref_next | M34: static | N34: barrier | O34: walk | P34: barrier | Q34: walk | R34: ref_next | S34: static | T34: wall | U34: static | V34: wall | W34: static | X34: wall | Y34: static | Z34: wall | AA34: static | AB34: wall | AC34: walk | AD34: barrier | AE34: climb | AF34: ref_next | AG34: walk | AH34: wall | AI34: static | AL34: wall | AM34: static | AN34: wall | AO34: static | AP34: wall | AQ34: static | AR34: wall | AS34: static | AT34: ref_next | AU34: static | AV34: ref_next | AW34: static | AX34: ref_next | AY34: static | BA34: 43 | BB34: 73 | BC34: 5 | BD34: 1 | BE34: M | BF34: M | BG34: 23.72 | BH34: 10 | BI34: 8 | BJ34: 1 | BK34: 2
A35: NCE2 | B35: 34 | C35: 5 | D35: 2 | E35: 45943 | F35: dark | G35: eel | H35: wall | I35: walk | J35: ref_next | K35: static | L35: ref_next | M35: static | N35: wall | O35: static | P35: wall | Q35: static | R35: wall | S35: static | T35: wall | U35: static | V35: wall | W35: static | X35: floor | Y35: walk | Z35: ref_next | AA35: walk | AB35: barrier | AC35: climb | AD35: barrier | AE35: climb | AF35: barrier | AG35: climb | AH35: barrier | AI35: climb | AL35: barrier | AM35: climb | AN35: barrier | AO35: climb | AP35: barrier | AQ35: climb | AR35: barrier | AS35: climb | AT35: barrier | AU35: climb | AV35: barrier | AW35: climb | AX35: barrier | AY35: climb | AZ35: eel in kōura side t90 | BA35: 74 | BB35: 74 | BD35: 2 | BE35: M | BF35: M | BG35: 26.68 | BH35: 14 | BI35: 8 | BJ35: 2 | BK35: 2
A36: NCE2 | B36: 35 | C36: 5 | D36: 3 | E36: 45943 | F36: dark | G36: control | H36: barrier | I36: static | J36: wall | K36: static | L36: barrier | M36: climb | N36: barrier | O36: climb | P36: barrier | Q36: climb | R36: barrier | S36: climb | T36: floor | U36: walk | V36: barrier | W36: climb | X36: barrier | Y36: climb | Z36: barrier | AA36: climb | AB36: barrier | AC36: climb | AD36: barrier | AE36: climb | AF36: barrier | AG36: static | AH36: wall | AI36: static | AL36: barrier | AM36: static | AN36: ref_back | AO36: static | AP36: ref_back | AQ36: static | AR36: ref_back | AS36: static | AT36: floor | AU36: walk | AV36: wall | AW36: static | AX36: barrier | AY36: walk | BA36: 49 | BB36: 75 | BC36: 16 | BD36: 3 | BE36: M | BF36: M | BG36: 25.38 | BH36: 9 | BI36: 6 | BJ36: 1 | BK36: 1
A37: NCE2 | B37: 36 | C37: 5 | D37: 4 | E37: 45943 | F37: dark | G37: catfish | H37: floor | I37: static | J37: floor | K37: walk | L37: barrier | M37: climb | N37: wall | O37: walk | P37: barrier | Q37: climb | R37: wall | S37: walk | T37: wall | U37: walk | V37: wall | W37: static | X37: barrier | Y37: static | Z37: ref_next | AA37: walk | AB37: ref_next | AC37: static | AD37: wall | AE37: walk | AF37: wall | AG37: walk | AH37: barrier | AI37: static | AL37: ref_next | AM37: static | AN37: ref_next | AO37: static | AP37: wall | AQ37: static | AR37: ref_next | AS37: static | AT37: barrier | AU37: static | AV37: barrier | AW37: walk | AX37: barrier | AY37: static | BA37: 76 | BB37: 76 | BD37: 4 | BE37: M | BF37: L | BG37: 30.28 | BH37: 19 | BI37: 8 | BJ37: 2 | BK37: 2
A38: NCE2 | B38: 37 | C38: 5 | D38: 5 | E38: 45943 | F38: dark | G38: eel | H38: wall | I38: static | J38: ref_next | K38: static | L38: ref_back | M38: static | N38: ref_back | O38: static | P38: ref_back | Q38: static | R38: ref_back | S38: static | T38: ref_back | U38: static | V38: ref_back | W38: static | X38: ref_back | Y38: static | Z38: ref_back | AA38: static | AB38: ref_back | AC38: static | AD38: ref_back | AE38: static | AF38: ref_back | AG38: static | AH38: ref_back | AI38: static | AL38: wall | AM38: static | AN38: floor | AO38: static | AP38: barrier | AQ38: climb | AR38: barrier | AS38: climb | AT38: barrier | AU38: climb | AV38: wall | AW38: static | AX38: ref_next | AY38: static | BA38: 77 | BB38: 77 | BD38: 5 | BE38: M | BF38: M | BG38: 26.63 | BH38: 12 | BI38: 8 | BJ38: 2 | BK38: 0
A39: NCE2 | B39: 38 | C39: 5 | D39: 6 | E39: 45943 | F39: dark | G39: control | H39: barrier | I39: climb | J39: barrier | K39: walk | L39: ref_back | M39: static | N39: ref_back | O39: static | P39: barrier | Q39: walk | R39: barrier | S39: climb | T39: barrier | U39: climb | V39: ref_back | W39: static | X39: ref_back | Y39: static | Z39: ref_open | AA39: static | AB39: ref_back | AC39: static | AD39: ref_back | AE39: static | AF39: ref_open | AG39: static | AH39: barrier | AI39: climb | AL39: ref_back | AM39: static | AN39: ref_back | AO39: static | AP39: ref_back | AQ39: static | AR39: ref_back | AS39: static | AT39: ref_back | AU39: static | AV39: ref_back | AW39: static | AX39: ref_back | AY39: static | BA39: 78 | BB39: 78 | BD39: 6 | BE39: M | BF39: S | BG39: 18.35 | BH39: 3 | BI39: 8 | BJ39: 2 | BK39: 2
A40: NCE2 | B40: 39 | C40: 5 | D40: 7 | E40: 45943 | F40: dark | G40: catfish | H40: wall | I40: walk | J40: wall | K40: walk | L40: barrier | M40: static | N40: barrier | O40: climb | P40: barrier | Q40: climb | R40: ref_next | S40: static | T40: barrier | U40: climb | V40: barrier | W40: climb | X40: barrier | Y40: climb | Z40: barrier | AA40: climb | AB40: barrier | AC40: climb | AD40: wall | AE40: climb | AF40: barrier | AG40: static | AH40: barrier | AI40: static | AL40: ref_back | AM40: static | AN40: ref_back | AO40: static | AP40: ref_back | AQ40: static | AR40: ref_back | AS40: static | AT40: ref_back | AU40: static | AV40: ref_open | AW40: static | AX40: ref_back | AY40: static | BA40: 79 | BB40: 79 | BD40: 7 | BE40: M | BF40: M | BG40: 24.24 | BH40: 10 | BI40: 6 | BJ40: 2 | BK40: 2
...

Sheet Long
A1: experiment | B1: exp_id | C1: round | D1: tank | E1: date | F1: light | G1: treatment | H1: location_T0 | I1: behaviour_T0 | J1: location_T300 | K1: behaviour_T300 | L1: notes_exp | M1: koura_id | N1: old_id | O1: hold_tank | P1: sex | Q1: size_class | R1: size_mm1 | S1: weight_g1 | T1: legs1 | U1: claws1 | V1: antenna1 | W1: note | X1: size_mm2 | Y1: weight_g2 | Z1: legs2 | AA1: claws2 | AB1: antenna2 | AC1: moult_date | AD1: notes_koura
A2: NCE3 | B2: 65 | C2: 9 | D2: 1 | E2: 45946 | F2: long | G2: catfish | H2: ref_back | I2: static | J2: ref_back | K2: static | L2: T=1110 | M2: 97 | O2: 9 | P2: M | Q2: L | R2: 30.22 | S2: 16 | T2: 6 | U2: 1 | V2: 2
A3: NCE3 | B3: 66 | C3: 9 | D3: 2 | E3: 45946 | F3: long | G3: eel | H3: wall | I3: static | L3: eel + kōura escaped found in gutter | M3: 98 | O3: 10 | P3: M | Q3: L | R3: 30.91 | S3: 21 | T3: 8 | U3: 2 | V3: 2
A4: NCE3 | B4: 67 | C4: 9 | D4: 3 | E4: 45946 | F4: long | G4: control | H4: ref_back | I4: static | J4: ref_back | K4: static | M4: 99 | O4: 11 | P4: M | Q4: M | R4: 25.21 | S4: 8 | T4: 8 | U4: 2 | V4: 2 | W4: soft | AC4: 45944
A5: NCE3 | B5: 68 | C5: 9 | D5: 4 | E5: 45946 | F5: long | G5: catfish | H5: barrier | I5: static | J5: ref_back | K5: static | M5: 100 | O5: 12 | P5: M | Q5: S | R5: 21.46 | S5: 6 | T5: 8 | U5: 2 | V5: 2
A6: NCE3 | B6: 69 | C6: 9 | D6: 5 | E6: 45946 | F6: long | G6: eel | H6: barrier | I6: climb | L6: eel + kōura escaped found on floor | M6: 78 | O6: 13 | P6: M | Q6: S | R6: 18.35 | S6: 3 | T6: 8 | U6: 2 | V6: 2
A7: NCE3 | B7: 70 | C7: 9 | D7: 6 | E7: 45946 | F7: long | G7: control | H7: barrier | I7: static | J7: wall | K7: static | M7: 102 | N7: 58 | O7: 14 | P7: M | Q7: M | R7: 26.87 | S7: 11 | T7: 7 | U7: 2 | V7: 2
A8: NCE3 | B8: 71 | C8: 9 | D8: 7 | E8: 45946 | F8: long | G8: catfish | H8: barrier | I8: walk | J8: barrier | K8: climb | M8: 84 | O8: 15 | P8: M | Q8: M | R8: 25.2 | S8: 11 | T8: 8 | U8: 2 | V8: 2
A9: NCE3 | B9: 72 | C9: 9 | D9: 8 | E9: 45946 | F9: long | G9: eel | H9: ref_back | I9: static | J9: wall | K9: static | L9: eel escaped | M9: 87 | O9: 16 | P9: M | Q9: S | R9: 21.26 | S9: 7 | T9: 6 | U9: 2 | V9: 2

Sheet GoPro
A1: date | B1: exp | C1: name_vid | D1: round | E1: camera | F1: first | G1: end | H1: fotos | I1: interval | J1: time_run | K1: time_in | L1: time_fin | M1: make text file
A2: 45931 | B2: NCE1 | C2: NCE1_R1_tank1-4 | D2: 1 | E2: 3 | F2: 10008 | G2: 13681 | H2: =G2-F2+1 -> 3674 | I2: 5 | J2: =IF(OR(H2="",I2=""),"", ((H2-1)*I2)/86400) -> 0.21255787 | L2: =K2+J2 -> 0.21255787 | M2: $min=10008; $max=13681; Get-ChildItem -Filter "G*.JPG" | Where-Object { $_.BaseName -match '^G(\d{7})$' -and ([int]$Matches[1] -ge $min) -and ([int]$Matches[1] -le $max) } | Sort-Object Name | ForEach-Object { "file '$($_.FullName)'" } | Set-Content files.txt
A3: 45931 | B3: NCE1 | C3: NCE1_R1_tank5-8 | D3: 1 | E3: 4 | F3: 12509 | G3: 16183 | H3: =G3-F3+1 -> 3675 | I3: 5 | J3: =IF(OR(H3="",I3=""),"", ((H3-1)*I3)/86400) -> 0.21261574 | L3: =K3+J3 -> 0.21261574 | M3: $min=12509; $max=16183; Get-ChildItem -Filter "G*.JPG" | Where-Object { $_.BaseName -match '^G(\d{7})$' -and ([int]$Matches[1] -ge $min) -and ([int]$Matches[1] -le $max) } | Sort-Object Name | ForEach-Object { "file '$($_.FullName)'" } | Set-Content files.txt
A4: 45932 | B4: NCE1 | C4: NCE1_R2_tank1-4 | D4: 2 | E4: 4 | F4: 13682 | G4: 17320 | H4: =G4-F4+1 -> 3639 | I4: 5 | J4: =IF(OR(H4="",I4=""),"", ((H4-1)*I4)/86400) -> 0.21053241 | L4: =K4+J4 -> 0.21053241 | M4: $min=13682; $max=17320; Get-ChildItem -Filter "G*.JPG" | Where-Object { $_.BaseName -match '^G(\d{7})$' -and ([int]$Matches[1] -ge $min) -and ([int]$Matches[1] -le $max) } | Sort-Object Name | ForEach-Object { "file '$($_.FullName)'" } | Set-Content files.txt
A5: 45932 | B5: NCE1 | C5: NCE1_R2_tank5-8 | D5: 2 | E5: 1 | F5: 12504 | G5: 16146 | H5: =G5-F5+1 -> 3643 | I5: 5 | J5: =IF(OR(H5="",I5=""),"", ((H5-1)*I5)/86400) -> 0.21076389 | L5: =K5+J5 -> 0.21076389 | M5: $min=12504; $max=16146; Get-ChildItem -Filter "G*.JPG" | Where-Object { $_.BaseName -match '^G(\d{7})$' -and ([int]$Matches[1] -ge $min) -and ([int]$Matches[1] -le $max) } | Sort-Object Name | ForEach-Object { "file '$($_.FullName)'" } | Set-Content files.txt
A6: 45933 | B6: NCE1 | C6: NCE1_R3_tank1-4 | D6: 3 | E6: 4 | F6: 17321 | G6: 20955 | H6: =G6-F6+1 -> 3635 | I6: 5 | J6: =IF(OR(H6="",I6=""),"", ((H6-1)*I6)/86400) -> 0.21030093 | L6: =K6+J6 -> 0.21030093 | M6: $min=17321; $max=20955; Get-ChildItem -Filter "G*.JPG" | Where-Object { $_.BaseName -match '^G(\d{7})$' -and ([int]$Matches[1] -ge $min) -and ([int]$Matches[1] -le $max) } | Sort-Object Name | ForEach-Object { "file '$($_.FullName)'" } | Set-Content files.txt
A7: 45933 | B7: NCE1 | C7: NCE1_R3_tank5-8 | D7: 3 | E7: 1 | F7: 16147 | G7: 19780 | H7: =G7-F7+1 -> 3634 | I7: 5 | J7: =IF(OR(H7="",I7=""),"", ((H7-1)*I7)/86400) -> 0.21024306 | L7: =K7+J7 -> 0.21024306 | M7: $min=16147; $max=19780; Get-ChildItem -Filter "G*.JPG" | Where-Object { $_.BaseName -match '^G(\d{7})$' -and ([int]$Matches[1] -ge $min) -and ([int]$Matches[1] -le $max) } | Sort-Object Name | ForEach-Object { "file '$($_.FullName)'" } | Set-Content files.txt
A8: 45936 | B8: NCE1 | C8: NCE1_R4_tank1-4 | D8: 4 | E8: 1 | F8: 19781 | G8: 19968 | H8: =G8-F8+1 -> 188 | I8: 5 | J8: =IF(OR(H8="",I8=""),"", ((H8-1)*I8)/86400) -> 0.010821759 | L8: =K8+J8 -> 0.010821759 | M8: $min=19781; $max=19968; Get-ChildItem -Filter "G*.JPG" | Where-Object { $_.BaseName -match '^G(\d{7})$' -and ([int]$Matches[1] -ge $min) -and ([int]$Matches[1] -le $max) } | Sort-Object Name | ForEach-Object { "file '$($_.FullName)'" } | Set-Content files.txt
A9: 45936 | B9: NCE1 | C9: NCE1_R4_tank5-8 | D9: 4 | E9: 3 | F9: 16184 | G9: 19813 | H9: =G9-F9+1 -> 3630 | I9: 5 | J9: =IF(OR(H9="",I9=""),"", ((H9-1)*I9)/86400) -> 0.21001157 | L9: =K9+J9 -> 0.21001157 | M9: $min=16184; $max=19813; Get-ChildItem -Filter "G*.JPG" | Where-Object { $_.BaseName -match '^G(\d{7})$' -and ([int]$Matches[1] -ge $min) -and ([int]$Matches[1] -le $max) } | Sort-Object Name | ForEach-Object { "file '$($_.FullName)'" } | Set-Content files.txt
A10: 45943 | B10: NCE2 | C10: NCE2_R5_tank1-4 | D10: 5 | E10: 3 | F10: 29814 | G10: 33456 | H10: =G10-F10+1 -> 3643 | I10: 5 | J10: =IF(OR(H10="",I10=""),"", ((H10-1)*I10)/86400) -> 0.21076389 | L10: =K10+J10 -> 0.21076389 | M10: $min=29814; $max=33456; Get-ChildItem -Filter "G*.JPG" | Where-Object { $_.BaseName -match '^G(\d{7})$' -and ([int]$Matches[1] -ge $min) -and ([int]$Matches[1] -le $max) } | Sort-Object Name | ForEach-Object { "file '$($_.FullName)'" } | Set-Content files.txt
A11: 45943 | B11: NCE2 | C11: NCE2_R5_tank5-8 | D11: 5 | E11: 4 | F11: 10956 | G11: 13415 | H11: =G11-F11+1 -> 2460 | I11: 5 | J11: =IF(OR(H11="",I11=""),"", ((H11-1)*I11)/86400) -> 0.14230324 | L11: =K11+J11 -> 0.14230324 | M11: $min=10956; $max=13415; Get-ChildItem -Filter "G*.JPG" | Where-Object { $_.BaseName -match '^G(\d{7})$' -and ([int]$Matches[1] -ge $min) -and ([int]$Matches[1] -le $max) } | Sort-Object Name | ForEach-Object { "file '$($_.FullName)'" } | Set-Content files.txt | N11: problem with the other gopro so thisone started after T90
A12: 45944 | B12: NCE2 | C12: NCE2_R6_tank1-4 | D12: 6 | E12: 3 | F12: 13457 | G12: 17074 | H12: =G12-F12+1 -> 3618 | I12: 5 | J12: =IF(OR(H12="",I12=""),"", ((H12-1)*I12)/86400) -> 0.20931713 | L12: =K12+J12 -> 0.20931713 | M12: $min=13457; $max=17074; Get-ChildItem -Filter "G*.JPG" | Where-Object { $_.BaseName -match '^G(\d{7})$' -and ([int]$Matches[1] -ge $min) -and ([int]$Matches[1] -le $max) } | Sort-Object Name | ForEach-Object { "file '$($_.FullName)'" } | Set-Content files.txt
A13: 45944 | B13: NCE2 | C13: NCE2_R6_tank5-8 | D13: 6 | E13: 4 | F13: 13416 | G13: 17036 | H13: =G13-F13+1 -> 3621 | I13: 5 | J13: =IF(OR(H13="",I13=""),"", ((H13-1)*I13)/86400) -> 0.20949074 | L13: =K13+J13 -> 0.20949074 | M13: $min=13416; $max=17036; Get-ChildItem -Filter "G*.JPG" | Where-Object { $_.BaseName -match '^G(\d{7})$' -and ([int]$Matches[1] -ge $min) -and ([int]$Matches[1] -le $max) } | Sort-Object Name | ForEach-Object { "file '$($_.FullName)'" } | Set-Content files.txt
A14: 45945 | B14: NCE2 | C14: NCE2_R7_tank1-4 | D14: 7 | E14: 3 | F14: 27077 | G14: 30697 | H14: =G14-F14+1 -> 3621 | I14: 5 | J14: =IF(OR(H14="",I14=""),"", ((H14-1)*I14)/86400) -> 0.20949074 | L14: =K14+J14 -> 0.20949074 | M14: $min=27077; $max=30697; Get-ChildItem -Filter "G*.JPG" | Where-Object { $_.BaseName -match '^G(\d{7})$' -and ([int]$Matches[1] -ge $min) -and ([int]$Matches[1] -le $max) } | Sort-Object Name | ForEach-Object { "file '$($_.FullName)'" } | Set-Content files.txt
A15: 45945 | B15: NCE2 | C15: NCE2_R7_tank5-8 | D15: 7 | E15: 4 | F15: 17037 | G15: 20659 | H15: =G15-F15+1 -> 3623 | I15: 5 | J15: =IF(OR(H15="",I15=""),"", ((H15-1)*I15)/86400) -> 0.20960648 | L15: =K15+J15 -> 0.20960648 | M15: $min=17037; $max=20659; Get-ChildItem -Filter "G*.JPG" | Where-Object { $_.BaseName -match '^G(\d{7})$' -and ([int]$Matches[1] -ge $min) -and ([int]$Matches[1] -le $max) } | Sort-Object Name | ForEach-Object { "file '$($_.FullName)'" } | Set-Content files.txt
A16: 45946 | B16: NCE2 | C16: NCE2_R8_tank1-4 | D16: 8 | E16: 3 | F16: 10698 | G16: 14310 | H16: =G16-F16+1 -> 3613 | I16: 5 | J16: =IF(OR(H16="",I16=""),"", ((H16-1)*I16)/86400) -> 0.20902778 | L16: =K16+J16 -> 0.20902778 | M16: $min=10698; $max=14310; Get-ChildItem -Filter "G*.JPG" | Where-Object { $_.BaseName -match '^G(\d{7})$' -and ([int]$Matches[1] -ge $min) -and ([int]$Matches[1] -le $max) } | Sort-Object Name | ForEach-Object { "file '$($_.FullName)'" } | Set-Content files.txt
A17: 45946 | B17: NCE2 | C17: NCE2_R8_tank5-8 | D17: 8 | E17: 4 | F17: 10660 | G17: 14273 | H17: =G17-F17+1 -> 3614 | I17: 5 | J17: =IF(OR(H17="",I17=""),"", ((H17-1)*I17)/86400) -> 0.20908565 | L17: =K17+J17 -> 0.20908565 | M17: $min=10660; $max=14273; Get-ChildItem -Filter "G*.JPG" | Where-Object { $_.BaseName -match '^G(\d{7})$' -and ([int]$Matches[1] -ge $min) -and ([int]$Matches[1] -le $max) } | Sort-Object Name | ForEach-Object { "file '$($_.FullName)'" } | Set-Content files.txt
A18: 45947 | B18: NCE3 | C18: NCE3_R9_tank1-4 | D18: 9 | E18: 3 | F18: 14311 | G18: 27762 | H18: =G18-F18+1 -> 13452 | I18: 5 | J18: =IF(OR(H18="",I18=""),"", ((H18-1)*I18)/86400) -> 0.77841435 | L18: =K18+J18 -> 0.77841435 | M18: $min=14311; $max=27762; Get-ChildItem -Filter "G*.JPG" | Where-Object { $_.BaseName -match '^G(\d{7})$' -and ([int]$Matches[1] -ge $min) -and ([int]$Matches[1] -le $max) } | Sort-Object Name | ForEach-Object { "file '$($_.FullName)'" } | Set-Content files.txt
A19: 45947 | B19: NCE3 | C19: NCE3_R9_tank5-8 | D19: 9 | E19: 4 | F19: 14274 | G19: 27708 | H19: =G19-F19+1 -> 13435 | I19: 5 | J19: =IF(OR(H19="",I19=""),"", ((H19-1)*I19)/86400) -> 0.77743056 | L19: =K19+J19 -> 0.77743056 | M19: $min=14274; $max=27708; Get-ChildItem -Filter "G*.JPG" | Where-Object { $_.BaseName -match '^G(\d{7})$' -and ([int]$Matches[1] -ge $min) -and ([int]$Matches[1] -le $max) } | Sort-Object Name | ForEach-Object { "file '$($_.FullName)'" } | Set-Content files.txt
A23: Round_1_Tank_1 | C23: Shelter
A24: 1012 | B24: 732 | C24: 778 | D24: 467
A25: 2036 | B25: 732 | C25: 911 | D25: 467
A26: 2036 | B26: 1312 | C26: 911 | D26: 549
A27: 1012 | B27: 1312 | C27: 778 | D27: 549
A28: Round_1_Tank_2
A29: 2036 | B29: 732
A30: 3008 | B30: 732
A31: 3008 | B31: 1292
A32: 2036 | B32: 1292
A33: Round_1_Tank_3
A34: 1116 | B34: 1752
A35: 2044 | B35: 1752
A36: 2044 | B36: 2340
A37: 1116 | B37: 2340
A38: Round_1_Tank_4
A39: 2044 | B39: 1680
A40: 2936 | B40: 1680
A41: 2936 | B41: 2344
A42: 2044 | B42: 2344
A43: Round_2_Tank_1
...

Sheet Feeding
A1: exp | B1: exp_id | C1: round | D1: exp_tank | E1: treatment | F1: liter | G1: date | H1: time_in | I1: day_starve | J1: start_food | K1: food_in_g | L1: total_fed | M1: left_after_24h | N1: fraction | O1: koura_id | P1: old_id | Q1: sex | R1: size_class | S1: size_mm | T1: weight_g | U1: legs | V1: claws | W1: antenna | X1: Moult_date | Y1: notes_koura
A2: feeding | B2: 1 | C2: 2 | D2: 1 | E2: catfish | F2: 5+1 | G2: 45953 | H2: 0.45833333 | I2: 0 | J2: 10 | K2: 0.4784 | L2: =J2 -> 10 | M2: 9.5 | N2: =M2/L2 -> 0.95 | O2: 17 | P2: 23 | Q2: M | R2: M | S2: 24.15 | T2: 8 | U2: 4 | V2: 2 | W2: 2
A3: feeding | B3: 2 | C3: 2 | D3: 2 | E3: eel | F3: 5+1 | G3: 45953 | H3: 0.45833333 | I3: 0 | J3: 10 | K3: 0.4506 | L3: =J3 -> 10 | M3: 10 | N3: =M3/L3 -> 1 | O3: 19 | P3: 17 | Q3: F | R3: M | S3: 25.35 | T3: 12 | U3: 7 | V3: 2 | W3: 2
A4: feeding | B4: 3 | C4: 2 | D4: 3 | E4: control | F4: 5+1 | G4: 45953 | H4: 0.45833333 | I4: 0 | J4: 10 | K4: 0.4785 | L4: =J4 -> 10 | M4: 9 | N4: =M4/L4 -> 0.9 | O4: 20 | P4: 14 | Q4: F | R4: M | S4: 26.52 | T4: 11 | U4: 8 | V4: 2 | W4: 2
A5: feeding | B5: 4 | C5: 2 | D5: 4 | E5: catfish | F5: 5+1 | G5: 45953 | H5: 0.45833333 | I5: 0 | J5: 10 | K5: 0.4909 | L5: =J5 -> 10 | M5: 10 | N5: =M5/L5 -> 1 | O5: 21 | Q5: M | R5: M | S5: 25.39 | T5: 9 | U5: 7 | V5: 2 | W5: 2 | X5: 15/10/25
A6: feeding | B6: 5 | C6: 2 | D6: 5 | E6: eel | F6: 5+1 | G6: 45953 | H6: 0.45833333 | I6: 0 | J6: 10 | K6: 0.4777 | L6: =J6 -> 10 | M6: 8 | N6: =M6/L6 -> 0.8 | O6: 22 | Q6: M | R6: M | S6: 28.55 | T6: 17 | U6: 8 | V6: 2 | W6: 2
A7: feeding | B7: 6 | C7: 2 | D7: 6 | E7: control | F7: 5+1 | G7: 45953 | H7: 0.45833333 | I7: 0 | J7: 10 | K7: 0.4799 | L7: =J7 -> 10 | M7: 10 | N7: =M7/L7 -> 1 | O7: 23 | P7: 9 | Q7: M | R7: M | S7: 24.46 | T7: 10 | U7: 8 | V7: 2 | W7: 2
A8: feeding | B8: 7 | C8: 2 | D8: 7 | E8: catfish | F8: 5+1 | G8: 45953 | H8: 0.45833333 | I8: 0 | J8: 10 | K8: 0.4608 | L8: =J8 -> 10 | M8: 10 | N8: =M8/L8 -> 1 | O8: 24 | Q8: M | R8: M | S8: 28.59 | T8: 15 | U8: 8 | V8: 1 | W8: 2
A9: feeding | B9: 8 | C9: 2 | D9: 8 | E9: eel | F9: 5+1 | G9: 45953 | H9: 0.45833333 | I9: 0 | J9: 10 | K9: 0.4636 | L9: =J9 -> 10 | M9: 9.5 | N9: =M9/L9 -> 0.95 | O9: 25 | P9: 30 | Q9: M | R9: M | S9: 26.55 | T9: 13 | U9: 7 | V9: 2 | W9: 2
A10: feeding | B10: 9 | C10: 2 | D10: 9 | E10: control | F10: 5+1 | G10: 45953 | H10: 0.45833333 | I10: 0 | J10: 10 | K10: 0.5055 | L10: =J10 -> 10 | M10: 10 | N10: =M10/L10 -> 1 | O10: 26 | Q10: M | R10: M | S10: 23.62 | T10: 8 | U10: 8 | V10: 2 | W10: 2 | X10: 24/10/25
A11: feeding | B11: 10 | C11: 2 | D11: 10 | E11: catfish | F11: 5+1 | G11: 45953 | H11: 0.45833333 | I11: 0 | J11: 10 | K11: 0.5168 | L11: =J11 -> 10 | M11: 10 | N11: =M11/L11 -> 1 | O11: 28 | Q11: M | R11: M | S11: 29.36 | T11: 17 | U11: 7 | V11: 2 | W11: 2
A12: feeding | B12: 11 | C12: 2 | D12: 11 | E12: eel | F12: 5+1 | G12: 45953 | H12: 0.45833333 | I12: 0 | J12: 10 | K12: 0.4749 | L12: =J12 -> 10 | M12: 10 | N12: =M12/L12 -> 1 | O12: 29 | P12: 11 | Q12: M | R12: M | S12: 29.46 | T12: 17 | U12: 8 | V12: 2 | W12: 2
A13: feeding | B13: 12 | C13: 2 | D13: 12 | E13: control | F13: 5+1 | G13: 45953 | H13: 0.45833333 | I13: 0 | J13: 10 | K13: 0.5009 | L13: =J13 -> 10 | M13: 10 | N13: =M13/L13 -> 1 | O13: 32 | P13: 13 | Q13: M | R13: M | S13: 23.96 | T13: 8 | U13: 6 | V13: 2 | W13: 2
A14: feeding | B14: 13 | C14: 2 | D14: 13 | E14: catfish | F14: 5+1 | G14: 45953 | H14: 0.45833333 | I14: 0 | J14: 10 | K14: 0.5255 | L14: =J14 -> 10 | M14: 10 | N14: =M14/L14 -> 1 | O14: 33 | Q14: M | R14: M | S14: 24.83 | T14: 10 | U14: 8 | V14: 2 | W14: 2
A15: feeding | B15: 14 | C15: 2 | D15: 14 | E15: eel | F15: 5+1 | G15: 45953 | H15: 0.45833333 | I15: 0 | J15: 10 | K15: 0.4943 | L15: =J15 -> 10 | M15: 10 | N15: =M15/L15 -> 1 | O15: 35 | Q15: M | R15: M | S15: 28.52 | T15: 14 | U15: 5 | V15: 2 | W15: 2
A16: feeding | B16: 15 | C16: 2 | D16: 15 | E16: control | F16: 5+1 | G16: 45953 | H16: 0.45833333 | I16: 0 | J16: 10 | K16: 0.5249 | L16: =J16 -> 10 | M16: 10 | N16: =M16/L16 -> 1 | O16: 37 | Q16: M | R16: M | S16: 26.6 | T16: 13 | U16: 8 | V16: 2 | W16: 2
A17: feeding | B17: 16 | C17: 2 | D17: 16 | E17: catfish | F17: 5+1 | G17: 45953 | H17: 0.45833333 | I17: 0 | J17: 10 | K17: 0.5217 | L17: =J17 -> 10 | M17: 9 | N17: =M17/L17 -> 0.9 | O17: 39 | Q17: M | R17: M | S17: 24.99 | T17: 10 | U17: 7 | V17: 2 | W17: 2
A18: feeding | B18: 17 | C18: 3 | D18: 1 | E18: eel | F18: 5+1 | G18: 45958 | H18: 0.41666667 | I18: 3 | J18: 10 | L18: =J18 -> 10 | M18: 10 | N18: =M18/L18 -> 1 | O18: 40 | P18: 30 | Q18: M | R18: M | S18: 23.44 | T18: 10 | U18: 8 | V18: 2 | W18: 2
A19: feeding | B19: 18 | C19: 3 | D19: 2 | E19: control | F19: 5+1 | G19: 45958 | H19: 0.41666667 | I19: 3 | J19: 10 | L19: =J19 -> 10 | M19: 3.5 | N19: =M19/L19 -> 0.35 | O19: 41 | Q19: M | R19: L | S19: 39.75 | T19: 42 | U19: 8 | V19: 2 | W19: 2
A20: feeding | B20: 19 | C20: 3 | D20: 3 | E20: catfish | F20: 5+1 | G20: 45958 | H20: 0.41666667 | I20: 3 | J20: 10 | L20: =J20 -> 10 | M20: 4.5 | N20: =M20/L20 -> 0.45 | O20: 42 | P20: 97 | Q20: M | R20: M | S20: 29.75 | T20: 16 | U20: 6 | V20: 1 | W20: 2
A21: feeding | B21: 20 | C21: 3 | D21: 4 | E21: eel | F21: 5+1 | G21: 45958 | H21: 0.41666667 | I21: 3 | J21: 10 | L21: =J21 -> 10 | M21: 7 | N21: =M21/L21 -> 0.7 | O21: 43 | P21: 77 | Q21: M | R21: M | S21: 26.6 | T21: 13 | U21: 7 | V21: 2 | W21: 0
A22: feeding | B22: 21 | C22: 3 | D22: 5 | E22: control | F22: 5+1 | G22: 45958 | H22: 0.41666667 | I22: 3 | J22: 10 | L22: =J22 -> 10 | M22: 5 | N22: =M22/L22 -> 0.5 | O22: 44 | Q22: M | R22: L | S22: 35.27 | T22: 30 | U22: 8 | V22: 2 | W22: 2
A23: feeding | B23: 22 | C23: 3 | D23: 6 | E23: catfish | F23: 5+1 | G23: 45958 | H23: 0.41666667 | I23: 3 | J23: 10 | L23: =J23 -> 10 | M23: 8 | N23: =M23/L23 -> 0.8 | O23: 45 | Q23: M | R23: M | S23: 25 | T23: 10 | U23: 8 | V23: 1 | W23: 2
A24: feeding | B24: 23 | C24: 3 | D24: 7 | E24: eel | F24: 5+1 | G24: 45958 | H24: 0.41666667 | I24: 3 | J24: 10 | L24: =J24 -> 10 | M24: 8 | N24: =M24/L24 -> 0.8 | O24: 46 | Q24: M | R24: M | S24: 28.41 | T24: 17 | U24: 8 | V24: 2 | W24: 2
A25: feeding | B25: 24 | C25: 3 | D25: 8 | E25: control | F25: 5+1 | G25: 45958 | H25: 0.41666667 | I25: 3 | J25: 10 | L25: =J25 -> 10 | M25: 7 | N25: =M25/L25 -> 0.7 | O25: 47 | Q25: M | R25: M | S25: 25.04 | T25: 11 | U25: 7 | V25: 2 | W25: 2
A26: feeding | B26: 25 | C26: 3 | D26: 9 | E26: catfish | F26: 5+1 | G26: 45958 | H26: 0.41666667 | I26: 3 | J26: 10 | L26: =J26 -> 10 | M26: 9 | N26: =M26/L26 -> 0.9 | O26: 48 | P26: 99 | Q26: M | R26: M | S26: 25.24 | T26: 10 | U26: 4 | V26: 0 | W26: 2
A27: feeding | B27: 26 | C27: 3 | D27: 10 | E27: eel | F27: 5+1 | G27: 45958 | H27: 0.41666667 | I27: 3 | J27: 10 | L27: =J27 -> 10 | M27: 9 | N27: =M27/L27 -> 0.9 | O27: 49 | Q27: M | R27: S | S27: 21.09 | T27: 8 | U27: 7 | V27: 2 | W27: 2
A28: feeding | B28: 27 | C28: 3 | D28: 11 | E28: control | F28: 5+1 | G28: 45958 | H28: 0.41666667 | I28: 3 | J28: 10 | L28: =J28 -> 10 | M28: 10 | N28: =M28/L28 -> 1 | O28: 50 | Q28: M | R28: L | S28: 32.94 | T28: 24 | U28: 7 | V28: 2 | W28: 2
A29: feeding | B29: 28 | C29: 3 | D29: 12 | E29: catfish | F29: 5+1 | G29: 45958 | H29: 0.41666667 | I29: 3 | J29: 10 | L29: =J29 -> 10 | M29: 5 | N29: =M29/L29 -> 0.5 | O29: 51 | Q29: M | R29: M | S29: 26.97 | T29: 13 | U29: 8 | V29: 2 | W29: 2
A30: feeding | B30: 29 | C30: 3 | D30: 13 | E30: eel | F30: 5+1 | G30: 45958 | H30: 0.41666667 | I30: 3 | J30: 10 | L30: =J30 -> 10 | M30: 7 | N30: =M30/L30 -> 0.7 | O30: 52 | P30: 26 | Q30: M | R30: L | S30: 30.1 | T30: 19 | U30: 8 | V30: 2 | W30: 2
A31: feeding | B31: 30 | C31: 3 | D31: 14 | E31: control | F31: 5+1 | G31: 45958 | H31: 0.41666667 | I31: 3 | J31: 10 | L31: =J31 -> 10 | M31: 9 | N31: =M31/L31 -> 0.9 | O31: 53 | P31: 102 | Q31: M | R31: M | S31: 26.62 | T31: 13 | U31: 7 | V31: 2 | W31: 1
A32: feeding | B32: 31 | C32: 3 | D32: 15 | E32: catfish | F32: 5+1 | G32: 45958 | H32: 0.41666667 | I32: 3 | J32: 10 | L32: =J32 -> 10 | M32: 5 | N32: =M32/L32 -> 0.5 | O32: 54 | Q32: M | R32: L | S32: 38.04 | T32: 34 | U32: 7 | V32: 2 | W32: 2
A33: feeding | B33: 32 | C33: 3 | D33: 16 | E33: eel | F33: 5+1 | G33: 45958 | H33: 0.41666667 | I33: 3 | J33: 10 | L33: =J33 -> 10 | M33: 10 | N33: =M33/L33 -> 1 | O33: 55 | P33: 87 | Q33: M | R33: S | S33: 21.59 | T33: 8 | U33: 5 | V33: 2 | W33: 2 | X33: 29/10/25 | Y33: SOFT
A34: feeding | B34: 33 | C34: 4 | D34: 1 | E34: control | F34: 5+1 | G34: 45959 | H34: 0.47916667 | I34: 4 | J34: 10 | L34: =J34 -> 10 | M34: 9.5 | N34: =M34/L34 -> 0.95 | O34: 56 | P34: 99 | Q34: M | R34: M | S34: 27.07 | T34: 12 | U34: 8 | V34: 1 | W34: 2
A35: feeding | B35: 34 | C35: 4 | D35: 2 | E35: catfish | F35: 5+1 | G35: 45959 | H35: 0.47916667 | I35: 4 | J35: 10 | L35: =J35 -> 10 | M35: 6.5 | N35: =M35/L35 -> 0.65 | O35: 57 | P35: 41 | Q35: M | R35: L | S35: 38.49 | T35: 40 | U35: 8 | V35: 2 | W35: 2
A36: feeding | B36: 35 | C36: 4 | D36: 3 | E36: eel | F36: 5+1 | G36: 45959 | H36: 0.47916667 | I36: 4 | J36: 10 | L36: =J36 -> 10 | M36: 8.5 | N36: =M36/L36 -> 0.85 | O36: 58 | P36: 70 | Q36: M | R36: M | S36: 25.21 | T36: 10 | U36: 6 | V36: 1 | W36: 1
A37: feeding | B37: 36 | C37: 4 | D37: 4 | E37: control | F37: 5+1 | G37: 45959 | H37: 0.47916667 | I37: 4 | J37: 10 | L37: =J37 -> 10 | M37: 8.5 | N37: =M37/L37 -> 0.85 | O37: 59 | P37: 80 | Q37: M | R37: M | S37: 25.84 | T37: 14 | U37: 8 | V37: 2 | W37: 2
A38: feeding | B38: 37 | C38: 4 | D38: 5 | E38: catfish | F38: 5+1 | G38: 45959 | H38: 0.47916667 | I38: 4 | J38: 10 | L38: =J38 -> 10 | M38: 9 | N38: =M38/L38 -> 0.9 | O38: 60 | Q38: M | R38: M | S38: 23.41 | T38: 9 | U38: 8 | V38: 1 | W38: 2
A39: feeding | B39: 38 | C39: 4 | D39: 6 | E39: eel | F39: 5+1 | G39: 45959 | H39: 0.47916667 | I39: 4 | J39: 10 | L39: =J39 -> 10 | M39: 9 | N39: =M39/L39 -> 0.9 | O39: 61 | P39: 81 | Q39: M | R39: L | S39: 30.38 | T39: 22 | U39: 8 | V39: 2 | W39: 2
A40: feeding | B40: 39 | C40: 4 | D40: 7 | E40: control | F40: 5+1 | G40: 45959 | H40: 0.47916667 | I40: 4 | J40: 10 | L40: =J40 -> 10 | M40: 10 | N40: =M40/L40 -> 1 | O40: 62 | P40: 92 | Q40: M | R40: S | S40: 20.48 | T40: 6 | U40: 8 | V40: 2 | W40: 2
...

Sheet pellet_weigth
A1: fresh pellets | D1: alluminium cups weight
A2: n | B2: weight_g | D2: n | E2: weight_g
A3: avg | B3: =AVERAGE(B4:B33) -> 0.054136667 | D3: avg | E3: =AVERAGE(E4:E33) -> 5.3276938
A4: 1 | B4: 0.0656 | D4: 1 | E4: 5.3126
A5: 2 | B5: 0.0494 | D5: 2 | E5: 5.3053
A6: 3 | B6: 0.0655 | D6: 3 | E6: 5.3022
A7: 4 | B7: 0.0603 | D7: 4 | E7: 5.3244
A8: 5 | B8: 0.0599 | D8: 5 | E8: 5.3046
A9: 6 | B9: 0.0638 | D9: 6 | E9: 5.3489
A10: 7 | B10: 0.0475 | D10: 7 | E10: 5.3219
A11: 8 | B11: 0.0438 | D11: 8 | E11: 5.3417
A12: 9 | B12: 0.0602 | D12: 9 | E12: 5.3342
A13: 10 | B13: 0.059 | D13: 10 | E13: 5.2823
A14: 11 | B14: 0.0608 | D14: 11 | E14: 5.3769
A15: 12 | B15: 0.0437 | D15: 12 | E15: 5.2651
... A19: 16 | B19: 0.0497 | D19: 16 | E19: 5.3566
A20: 17 | B20: 0.0583
A21: 18 | B21: 0.0459
A22: 19 | B22: 0.0587
A23: 20 | B23: 0.0465
A24: 21 | B24: 0.0654
A25: 22 | B25: 0.0529
A26: 23 | B26: 0.061
A27: 24 | B27: 0.0624
A28: 25 | B28: 0.0411
A29: 26 | B29: 0.0599
A30: 27 | B30: 0.043
A31: 28 | B31: 0.0422
... A33: 30 | B33: 0.0505

Sheet Feeding2
A1: exp | B1: round | C1: exp_tank | D1: treatment | E1: liter | F1: date | G1: time_in | H1: day_starve | I1: start_food | J1: food_in_g | K1: left_after_4h | L1: extra_food | M1: total_fed | N1: left_after_24h | O1: fraction | P1: extra_food2 | Q1: 48h | R1: tot_fed2 | S1: tot_eat_p | T1: tot_fed_g | U1: w_empty_tray | V1: w_tot | W1: residue_g | X1: tot_eat_g | Y1: notes_exp | Z1: koura_id | AA1: old_id | AB1: sex | AC1: size_class | AD1: size_mm1 | AE1: weight_g1 | AF1: legs1 | AG1: claws1 | AH1: antenna1 | AI1: size_mm2 | AJ1: weight_g2 | AK1: legs2 | AL1: claws2 | AM1: antenna2 | AN1: Moult_date | AO1: notes_koura
A2: Feeding | B2: 1 | C2: 1 | D2: control | E2: 7+1 | F2: 45937 | G2: 0.5 | H2: 2 | I2: 5 | K2: 2 | L2: 5 | M2: =I2+L2 -> 10 | N2: 7 | O2: =N2/M2 -> 0.7 | P2: 0 | Q2: 2 | R2: =I2+L2+P2 -> 10 | S2: =R2-Q2 -> 8 | T2: =R2*pellet_weigth!$B$3 -> 0.54136667 | U2: 5.3126 | V2: 5.3325 | W2: =V2-U2 -> 0.0199 | X2: =T2-W2 -> 0.52146667 | Y2: each tank 7 liter + 1 liter treatment water | Z2: 1 | AA2: 27 | AB2: F | AC2: M | AD2: 28.66 | AE2: 16 | AF2: 8 | AG2: 2 | AH2: 2
A3: Feeding | B3: 1 | C3: 2 | D3: catfish | E3: 7+1 | F3: 45937 | G3: 0.5 | H3: 2 | I3: 5 | K3: 5 | L3: 0 | M3: =I3+L3 -> 5 | N3: 5 | O3: =N3/M3 -> 1 | P3: 0 | Q3: 4.5 | R3: =I3+L3+P3 -> 5 | S3: =R3-Q3 -> 0.5 | T3: =R3*pellet_weigth!$B$3 -> 0.27068333 | U3: 5.3053 | V3: 5.3488 | W3: =V3-U3 -> 0.0435 | X3: =T3-W3 -> 0.22718333 | Y3: each tank 7 liter + 1 liter treatment water | Z3: 2 | AA3: 30 | AB3: F | AC3: M | AD3: 27.29 | AE3: 12 | AF3: 8 | AG3: 2 | AH3: 2
A4: Feeding | B4: 1 | C4: 3 | D4: eel | E4: 7+1 | F4: 45937 | G4: 0.5 | H4: 2 | I4: 5 | K4: 0 | L4: 5 | M4: =I4+L4 -> 10 | N4: 1 | O4: =N4/M4 -> 0.1 | P4: 5 | Q4: 4.5 | R4: =I4+L4+P4 -> 15 | S4: =R4-Q4 -> 10.5 | T4: =R4*pellet_weigth!$B$3 -> 0.81205 | U4: 5.3022 | V4: 5.4925 | W4: =V4-U4 -> 0.1903 | X4: =T4-W4 -> 0.62175 | Y4: each tank 7 liter + 1 liter treatment water | Z4: 3 | AA4: 18 | AB4: F | AC4: M | AD4: 28.54 | AE4: 16 | AF4: 8 | AG4: 2 | AH4: 2
A5: Feeding | B5: 1 | C5: 4 | D5: control | E5: 7+1 | F5: 45937 | G5: 0.5 | H5: 2 | I5: 5 | K5: 4 | L5: 0 | M5: =I5+L5 -> 5 | N5: 4 | O5: =N5/M5 -> 0.8 | P5: 0 | Q5: 0 | R5: =I5+L5+P5 -> 5 | S5: =R5-Q5 -> 5 | T5: =R5*pellet_weigth!$B$3 -> 0.27068333 | U5: 5.3244 | V5: 5.3719 | W5: =V5-U5 -> 0.0475 | X5: =T5-W5 -> 0.22318333 | Y5: each tank 7 liter + 1 liter treatment water | Z5: 4 | AA5: 7 | AB5: F | AC5: L | AD5: 30.81 | AE5: 20 | AF5: 8 | AG5: 2 | AH5: 2
A6: Feeding | B6: 1 | C6: 5 | D6: catfish | E6: 7+1 | F6: 45937 | G6: 0.5 | H6: 2 | I6: 5 | K6: 5 | L6: 0 | M6: =I6+L6 -> 5 | N6: 4.5 | O6: =N6/M6 -> 0.9 | P6: 0 | Q6: 0.5 | R6: =I6+L6+P6 -> 5 | S6: =R6-Q6 -> 4.5 | T6: =R6*pellet_weigth!$B$3 -> 0.27068333 | U6: 5.3046 | V6: 5.3333 | W6: =V6-U6 -> 0.0287 | X6: =T6-W6 -> 0.24198333 | Y6: each tank 7 liter + 1 liter treatment water | Z6: 5 | AB6: F | AC6: S | AD6: 20.21 | AE6: 5 | AF6: 8 | AG6: 2 | AH6: 2
A7: Feeding | B7: 1 | C7: 6 | D7: eel | E7: 7+1 | F7: 45937 | G7: 0.5 | H7: 2 | I7: 5 | K7: 1 | L7: 5 | M7: =I7+L7 -> 10 | N7: 5 | O7: =N7/M7 -> 0.5 | P7: 0 | Q7: 5 | R7: =I7+L7+P7 -> 10 | S7: =R7-Q7 -> 5 | T7: =R7*pellet_weigth!$B$3 -> 0.54136667 | U7: 5.3489 | V7: 5.4973 | W7: =V7-U7 -> 0.1484 | X7: =T7-W7 -> 0.39296667 | Y7: each tank 7 liter + 1 liter treatment water | Z7: 6 | AB7: F | AC7: M | AD7: 23.21 | AE7: 8 | AF7: 6 | AG7: 1 | AH7: 2
A8: Feeding | B8: 1 | C8: 7 | D8: control | E8: 7+1 | F8: 45937 | G8: 0.5 | H8: 2 | I8: 5 | K8: 0 | L8: 5 | M8: =I8+L8 -> 10 | N8: 2.5 | O8: =N8/M8 -> 0.25 | P8: 5 | Q8: 5 | R8: =I8+L8+P8 -> 15 | S8: =R8-Q8 -> 10 | T8: =R8*pellet_weigth!$B$3 -> 0.81205 | U8: 5.3219 | V8: 5.5108 | W8: =V8-U8 -> 0.1889 | X8: =T8-W8 -> 0.62315 | Y8: each tank 7 liter + 1 liter treatment water | Z8: 7 | AA8: 35 | AB8: F | AC8: M | AD8: 25.55 | AE8: 11 | AF8: 7 | AG8: 2 | AH8: 1
